Workbook

Sheet 입력시트
B2: 구분 | C2: 내용 | D2: 비고
B3: 대표자명
B4: 개인대표자명 OR 법인명 | D4: 개인이면 개인 법인이면 법인 | E4: 한번 더 입력 함수 떄문에
B5: 예금주명 | D5: 법인이면 법인명
B6: 주민등록번호
B7: 상호명
B8: 사업자등록번호
B9: 법인등록번호
B10: 휴대폰번호
B11: 은행명
B12: 계좌번호
B13: 기장료
B14: 사업장소재지
C16: 다시 새롭게 매번 작성
C17: 그 외엔 제발 건들지 마세요

Sheet 기장계약서표지 

Sheet 기장계약서 1 
B2: 세무서비스 계약서
B5: [계약종류]
B7: √ 기장대리
B8: ▢ 세무조정서비스
B9: ▢ 세무자문(고문)서비스
B10: ▢ 조세불복 (▢ 과세적부심사청구 ▢ 이의신청 ▢ 심사․심판청구 ▢ 조세소송 대응)
B11: ▢ 재산세제 (▢ 상속세 ▢ 증여세 ▢ 양도소득세)
B12: ▢ (모의)세무조사 입회 대리
B13: ▢ 회계아웃소싱
B14: ▢ 조세환급(경정청구) 컨설팅
B15: ▢ 법인컨설팅 (▢ 명의신탁주식환원 ▢ 가지급금정리 ▢ 주식이동 ▢ 법인전환 ▢ 기타)
B17: 【 위 임 자 】
B19: 사업자등록번호 | C19: =입력시트!C8 -> 0
B20: 회 사 명 | C20: =입력시트!C7 -> 0
B21: 연 락 처 | C21: (전화) | D21: =입력시트!C10 -> 0 | F21: (주민번호) | G21: =입력시트!C6 -> 0
B22: 대 표 자 | C22: =MID(입력시트!C3,1,1)&" "&MID(입력시트!C3,2,1)&" "&MID(입력시트!C3,3,1)&" 대 표 님" -> 대 표 님
B24: 【 수 임 자 】
B26: 사업자등록번호 | C26: 306-29-93669
B27: 주업태 및 종목 | C27: ① | D27: 전문,과학 및 기술서비스업 | F27: ② | G27: 세무사
B28: 회 사 명 | C28: 코드세무회계
B29: 사업장 소재지 | C29: 경기도 성남시 분당구 삼평동 판교역로192번길 14-2 912,913호
B30: 블 로 그 | C30: https://blog.naver.com/juhee744
B31: 연 락 처 | C31: (핸드폰) | E31: 010-7276-2430 | F31: (e-mail) | G31: codetax.help@gmail.com
C32: (팩 스) | E32: 0506-200-1788
B33: 대 표 자 | C33: 정 주 희 세 무 사
B43: 본 계약은 위임자가 영위하는 사업과 관련된 세무서비스의 범위, 보수 등을 정하는 것이 목적으로 한다.
B45: 제 1 조 (세무서비스의 범위)
B46: ① 수임자는 세무사법에서 정한 세무대리인으로서 제공하는 세무서비스의 업무범위는 아래의 항목으로 한정한다. 위임자는 본 계약에서 한정한 업무의 범위를 벗어나는 세무서비스를 의뢰할 경우 별도의 계약을 하여야 한다.
B48: [기본 업무]
B49: 1. 법인세(또는 소득세) 신고를 위한 기장대리(또는 장부작성)(이하 "일반기장업무"라 함)
B50: 2. 세무신고를 위한 결산업무(년1회) (이하 "결산업무"라 함)
B51: 3. 세무조정업무(이하 "세무조정업무"라 함)
B52: 4. 법인세(또는 소득세) 및 부가가치세 신고업무
B53: 5. 원천세 신고 및 연말정산(10인 이내)
B54: 6. 4대보험 신고관련 업무(자격취득, 자격상실, 보수총액신고)
B55: ② 위 ①항의 범위를 포함되지 않는 업무범위는 아래와 같다.
B56: 1. 성실신고확인
... B63: ③ 위 ①항 2호의 결산업무의 시기는 아래와 같다. 다만, 해당 결산시기 이외에 추가적인 결산을 요청하는 경우에는 별도의 수수료를 지급하여야 한다.
B65: 일반 사업자 | C65: 개인 | D65: 과세기간 종료일의 익년 5월 1일 ~ 5월 31일
C66: 법인 | D66: 과세기간 종료일로부터 3개월이 되는 달의 1일 ~ 말일
...

Sheet 기장계약서 2 
B2: [별첨 1] 기장 및 세무조정 세무서비스 보수표
B4: 1. 기장보수표 (부가가치세 별도)
O5: (단위 : 원)
B6: 구분 | C6: 업무내용 및 범위 | H6: 기준금액 | L6: 月 보 수 기 준
H7: (자산 또는 수입금액) | L7: 개 인 | N7: 법 인
B8: 일반형 | C8: · 원천세 신고 (10인 기준) · 4대보험 신고관련 업무 (10인 기준) (자격취득/상실신고, 보수총액신고) · 지급명세서 제출 · 연말정산 (10인 기준) · 부가가치세 신고 · 신용카드매입세액공제 · 면세사업자현황신고 · 계좌 내역정리 및 검토(법인) · 사업관련 기본 세무 상담 | J8: 3억 이하 | L8: 100000 | N8: 150000
H9: 3억 초과 | J9: 5억 이하 | L9: 150000 | N9: 200000
H10: 5억 초과 | J10: 10억 이하 | L10: 200000 | N10: 250000
H11: 10억 초과 | J11: 20억 이하 | L11: 250000 | N11: 300000
H12: 20억 초과 | J12: 30억 이하 | L12: 300000 | N12: 400000
H13: 30억 초과 | J13: 40억 이하 | L13: 400000 | N13: 500000
H14: 40억 초과 | J14: 50억 이하 | L14: 500000 | N14: 600000
H15: 50억 초과 | L15: 50억 초과는 각 10억 증가시마다 8만원(법인 10만원)씩 가산
B16: 고급형 | C16: · 일반형 모두 포함 · 매월 결산 · 분기별 결산 분석(재무비율) | H16: 분기 결산 | L16: 일반형 보수 +500,000 ~ | N16: 일반형 보수 +1,000,000 ~
B17: Prior-ity 서비스 | C17: · 고급형 업무 모두 포함 · 법인 관련 컨설팅 · 세금계산서 발급 대행 · 미수금 분석 | H17: 월 결산 | L17: 일반형 보수 +1,000,000 ~ | N17: 일반형 보수 +2,000,000 ~
B18: 기타 옵션 | C18: 세금계산서 발행 | H18: 매월 5개 이하 | L18: 30000
H19: 매월 10개 이하 | L19: 50000
H20: 매월 10개 초과 | L20: 개당 5,000
C21: 온라인 매출 | H21: 5개 초과 ~ 10개 이하 | L21: 50000 | N21: 100000
H22: 10개 초과 ~ 15개 이하 | L22: 70000 | N22: 150000
H23: 15개 초과 ~ 20개 이하 | L23: 100000 | N23: 200000
H24: 20개 초과 ~ 30개 이하 | L24: 150000 | N24: 300000
H25: 30개 초과 | L25: 200000 | N25: 400000
C26: 원천세 10인 이상 | H26: 추가 10인당 | L26: 월 2만원씩 추가
C27: 연말정산 10인 이상 | H27: 10인 초과 인원당 | L27: 초과 인원 당 5,000
C28: 구분경리 | H28: 월 산정 보수의 50% 가산
C29: 본지점 | H29: 본점 및 지점 개별 매출액 기준으로 각각 산정
B31: 2. 세무조정보수표 (부가가치세 별도)
O32: (단위 : 원)
B33: 수입금액 | D33: 개 인 | J33: 법 인
B34: 1억원 이하 | D34: 440,000원 | J34: 550,000원
B35: 1억원초과 ~ 3억원이하 | D35: 440,000원 | E35: + | F35: 1억원 | G35: 초과액 | H35: × | I35: 0.00155 | J35: 550,000원 | K35: + | L35: 1억원 | M35: 초과액 | N35: × | O35: 0.00185
B36: 3억원초과 ~ 5억원이하 | D36: 803,000원 | E36: + | F36: 3억원 | G36: 초과액 | H36: × | I36: 0.00125 | J36: 984,500원 | K36: + | L36: 3억원 | M36: 초과액 | N36: × | O36: 0.00155
B37: 5억원초과 ~ 10억원이하 | D37: 1,078,000원 | E37: + | F37: 5억원 | G37: 초과액 | H37: × | I37: 0.00105 | J37: 1,325,500원 | K37: + | L37: 5억원 | M37: 초과액 | N37: × | O37: 0.00125
B38: 10억원초과 ~ 20억원이하 | D38: 1,655,500원 | E38: + | F38: 10억원 | G38: 초과액 | H38: × | I38: 0.0007 | J38: 2,013,000원 | K38: + | L38: 10억원 | M38: 초과액 | N38: × | O38: 0.00105
B39: 20억원초과 ~ 50억원이하 | D39: 2,425,500원 | E39: + | F39: 20억원 | G39: 초과액 | H39: × | I39: 0.0004 | J39: 3,168,000원 | K39: + | L39: 20억원 | M39: 초과액 | N39: × | O39: 0.0006
B40: 50억원초과 ~ 300억원이하 | D40: 3,745,500원 | E40: + | F40: 50억원 | G40: 초과액 | H40: × | I40: 0.0003 | J40: 5,148,000원 | K40: + | L40: 50억원 | M40: 초과액 | N40: × | O40: 0.0004
B41: 300억원 초과 | D41: 11,995,500원 | E41: + | F41: 300억원 | G41: 초과액 | H41: × | I41: 0.00025 | J41: 16,148,000원 | K41: + | L41: 300억원 | M41: 초과액 | N41: × | O41: 0.0003
B43: ∗ 본지점이 있는 경우 지점당 계산
B45: ∗ 성실신고 확인대상 : 위 조정료와 별도로 성실신고 확인비용(개인 200만원, 법인 250만원) 수수료 청구

Sheet CMS 
B2: CMS 출금이체 이용 신청서
D3: (신청 구분(택1): ■신규 / □변경)
B5: ◈ 수납기관 및 요금정보(수납기관 기재란)
B7: 수납 기관명 | D7: 위너세무회계 본점 | F7: 대표자명 | H7: 정주희
B8: 사업장 주소 | D8: 경기도 성남시 분당구 판교역로192번길 14-2, 912,913호(삼평동, 골드타워)
B9: 사업자등록번호 | D9: 306-29-93669 | F9: 수납 요금종류 | H9: 기장료
B10: 출금통장 기재내역 | D10: 기장료 | F10: 수납 요금 | H10: =입력시트!C13 -> 0
B11: 이체 시작 월 | D11: 2026년 01월 | F11: 지정 출금일 | H11: 매월 25 일
B13: ◈ 출금이체 신청정보(신청인 기재란)
B14: 신청인명 | C14: =입력시트!C3 -> 0 | E14: 예금(카드)주와의 관계 | G14: 본인
B15: 신청인연락처 | C15: =입력시트!C10 -> 0 | E15: 신청인 휴대번호 | G15: =입력시트!C10 -> 0
B16: 출금이체 결제수단 | C16: (택1) ■ 계좌 / □신용카드
B17: 예금주명 (신용카드 발급자명) | C17: =입력시트!C5 -> 0 | E17: 주민등록번호 | G17: =LEFT(입력시트!C6,7) & "*******" -> *******
B19: 은행(카드사)명 | C19: =입력시트!C11 -> 0 | E19: 사업자등록번호 | G19: =입력시트!C8 -> 0
B20: 계좌(카드)번호 | C20: =입력시트!C12 -> 0 | E20: 카드 유효기간 | G20: / (월 / 년)
B21: 예금주(카드) 연락처 | C21: =C15 -> 0 | E21: 예금주(카드) 휴대번호 | G21: =C15 -> 0
B22: ※ 평생계좌(휴대폰번호)번호, 법인공용카드, 선불카드, 해외발행카드 등 일부 계좌 및 카드는 서비스 신청이 불가합니다.
B23: [개인정보 수집 및 이용 동의]  수집 및 이용목적: CMS 출금이체를 통한 요금 수납, 민원처리 및 동의여부 통지,  수집 항목: 신청인(성명, 연락처, 휴대번호), 예금(카드)주명, 은행(카드)명, 계좌(카드)번호, 생년월일(사업자등록번호), 카드유효기간  보유 및 이용기간: 수집 이용 동의일부터 자동이체서비스 종료일(해지일)까지며, 보유는 해지일로부터 5년간 보존 후 파기(관계 법령에 의거) 신청자는 개인정보 수집 및 이용을 거부할 수 있습니다. 단, 거부하는 경우 출금이체 신청이 정상적으로 처리되지 않습니다. 동의함■ 동의 안함□
B25: 신청자는 개인정보 수집 및 이용을 거부할 수 있습니다. 단, 거부하는 경우 출금이체 신청이 정상적으로 처리되지 않습니다.
B26: 동의함■ 동의 안함□
B27: [개인정보 제3자 제공 동의]  개인정보를 제공받는 자: 나이스페이먼츠 주식회사, 은행(산업/기업/국민/외환/수협/농협/우리/SC제일/씨티/대구/부산/광주/제주/전북/경남/새마을/신협/우체국/하나/신한/케이/카카오/토스), 카드사(국민/비씨/롯데/삼성/NH농협/현대/신한/하나/우리)  개인정보를 제공받는 자의 개인정보 이용 목적: CMS 출금이체 서비스 제공 및 출금동의 확인, 신규 등록 및 해지 사실 확인 및 통지, 민원 처리  제공하는 개인정보의 항목: 신청(성명, 연락처, 휴대번호), 예금(카드)주명, 은행(카드)명, 계좌(카드)번호, 생년월일(사업자등록번호), 카드유효기간  개인정보를 제공받는 자의 개인정보 보유 및 이용기간: CMS 출금이체 신청부터 해지까지. 단, 관련 법령에 의거 일정기간 보유.
B31: 신청자는 개인정보 수집 및 이용을 거부할 수 있습니다. 단, 거부하는 경우 출금이체 신청이 정상적으로 처리되지 않습니다
B32: 동의함■ 동의 안함□
B33: [출금이체 동의여부 및 해지사실 통지안내] 나이스페이먼츠㈜ 및 금융기관(은행 및 카드사)은 CMS 서비스의 안정적 운영을 위하여 고객의 연락처 정보를 활용하여 문자메세지, 유선 등으로 고객의 자동이체 동의 여부 및 해지사실을 통지 할 수 있습니다.
B34: [금융거래정보의 제공동의서] 본 신청과 관련하여 본인은 위 기재한 금융거래정보(신청인(성명,연락처), 예금주명, 예금주휴대폰번호, 출금은행명, 계좌번호, 예금주 생년월일(사업자등록번호)를 자동이체신규 신청하는 때로부터 서면으로 해지 신청할 때까지 나이스페이먼츠㈜, 금융기관, 공공금융기관에 제공하는 것에 대하여 [금융실거래 및 비밀보장에 관련한 법률] 의 규정에 따라 동의합니다.
B35: 출금이체 서비스 약관
B36: 1. 신청자는 본 신청서에 서명하거나 공인인증 및 그에 준하는 전자 인증절차를 통함으로써 본 서비스를 이용할 수 있습니다. 2. 회사는 서비스 제공을 위하여 이용자가 제출한 지급결제수단 정보를 해당 금융기관(통신사 포함)에 제공할 수 있습니다. 3. 자동이체 개시일을 이용자가 지정하지 않은 경우 재화 등을 공급하는 자로부터 사전 통지 받은 납기일을 최초 개시일로 하며, 출금은 이용업체와 협의한 날짜에 계좌출금이 이루어 집니다. 4. 출금이체 금액은 해당 지정 출금일 영업 시간 내에 입금된 예금(지정출금일에 입금된 타점권은 제외)에 한하여 출금 처리 되며, 출금이체 금액의 이의가 있는 경우에는 이용업체에 협의하여 조정키로 합니다. 5. 납기일에 동일한 수종의 자동이체 청구가 있는 경우 이체 우선 순위는 용자의 | F36: 거래 금융기관이 정하는 바에 따릅니다. 6. 자동이체 납부일이 영업일이 아닌 경우에는 다음 영업일을 납부일로 합니다. 7. 이용자가 자동이체 신청(신규, 해지, 변경)을 원하는 경우 해당 납기일 30일 전까지 회사에 통지해야 합니다. 8. 이용자가 제출한 지급결제수단의 잔액(예금한도, 신용한도 등)이 예정 결제금액보다 부족하거나 지급제한, 연체 등 납부자의 과실에 의해 발생하는 손해의 책임은 이용자에게 있습니다. 9. 이용자가 금융기관 및 회사가 정하는 기간 동안 자동이체 이용 실적이 없는 경우 사전 통지 후 자동이체를 해지할 수 있습니다. 10. 회사는 이용자와의 자동이체서비스 이용과 관련된 구체적인 권리, 의무를 정하기 위하여 본 약관과는 별도로 자동이체서비스이용약관을 제정할 수 있습니다
B39: 위와 같이 금융거래정보의 제공 및 개인정보 수집 및 이용, 개인정보 제3자 제공에 동의하며, 출금이체 서비스 약관을 확인하고 CMS출금이체 이용을 신청합니다.
B40: 이용을 신청합니다. | E40: =TODAY() -> 46099
E41: 신청인 | F41: =입력시트!C3 & " (인)" -> (인) | G41: 예금(카드)주 동의란 | H41: =입력시트!C3 & " (인)" -> (인)
B42: *신청인과 예금주/카드주가 상이한 경우에는 예금주/카드주가 의 동의 필요하며, 날인 또는 서명은 출금통장의 거래

Sheet 수임동의
B2: 【별지 제6호 서식】
B3: 홈택스 세무대리정보 이용(해지)신청서
B4: 접수번호
B6: 1.신청인 및 정보이용(해지) 사업장 | C6: ① 성명(대표자명) | D6: ② 주민등록번호(외국인등록번호 등)
C7: =입력시트!C3 -> 0 | D7: =입력시트!C6 -> 0
C8: ③-1 상호(법인명) | D8: ④-1 사업자등록번호
C9: =입력시트!C7 -> 0 | D9: =입력시트!C8 -> 0
C10: ③-2 | D10: ④-2
C11: ③-3 | D11: ④-3
C12: ⑤ 연락처(전화번호 : 010-1234-1234 )
B14: 2.신청 구분 | C14: ⑥ 정보이용 신청 ■⑦ 정보이용 해지신청 □
B15: 3.세무대리정보 이용 구분 등 (정보이용 신청 시 작성) | C15: ⑧ 세무대리정보이용 구분 및 기간 ▶ 기장대리 : 동의 처리일로부터 해지일까지 ■ ▶ 신고대리 : 동의 처리일로부터 당해 세무신고의 신고기한까지 □ 외부조정(법인) : 동의 처리일로부터 당해 세무신고의 신고기한까지 □ ※ 세무대리정보 이용 범위:『홈택스 이용에 관한 규정』 제54조의 정보 ※ 신청인의 개인정보보호를 위하여 세무대리인과 위임계약이 해지된 경우 반드시 신청인 또는 세무대리인이 홈택스에서 수임등록을 해지하시기 바랍니다.
B20: 4.정보이용(해지) 세무대리인 | C20: ⑨ 성명(상호) 위너세무회계 본점 | D20: ⑩ 사업자등록번호 306-29-93669
C21: ⑪ 세무사관리번호 Z-2882-7 | D21: ⑫ 연락처
D22: (전화번호 : 010-7276-2430)
B23: 상기 세무대리인이 국세청 홈택스에서 제공되는 신청인의 세무관련 정보 이용(해지)에 대하여 동의합니다.
B24: =TODAY() -> 46099
B25: =IF(입력시트!C4="","신 청 인 : (서명 또는 인)","신 청 인 : " & 입력시트!C4 & " (서명 또는 인)") -> 신 청 인 : (서명 또는 인)
B26: 세무서장 귀하
B28: 위 임 장 (대리인에게 위임하는 경우 작성)
B29: 위 신청인 본인은 아래 위임받은 사람에게 홈택스 세무대리정보 이용(해지)신청에 관한
B30: 모든 권리와 의무를 위임합니다.
B31: =IF(입력시트!C4="","위 임 하 는 사 람 : (서명 또는 인)","위 임 하 는 사 람 : " & 입력시트!C4 & " (서명 또는 인)") -> 위 임 하 는 사 람 : (서명 또는 인)
B32: 위임받은 | C32: 성 명 정 주 희 | D32: 주민등록번호 930320-2168311
B33: 사 람 | C33: 위임하는 사람과의 관계 세무대리인 | D33: 연락처(전화번호 : 010-7276-2430 )
B35: 개인정보 수집 ․ 이용에 대한 동의(개인정보보호법 제24조)
B36: ※ 동의를 거부할 권리가 있으며, 거부할 경우 신청서 처리 불가능 등의 불이익이 따를 수 있습니다.
B37: ○ 수집 ․ 이용목적 (신청서 처리, 사후관리 등) ○ 보유 ․ 이용기간 ( 5년 )
B38: ○ 수집대상 고유식별정보 (주민등록번호, 외국인등록번호, 여권번호 등)
B39: ■상기내용에 대해 동의합니다. □ 상기내용에 대해 동의하지 않습니다.
B40: =IF(입력시트!C4="","신 청 인 : (서명 또는 인)","신 청 인 : " & 입력시트!C4 & " (서명 또는 인)") -> 신 청 인 : (서명 또는 인) | D40: 위임받은 사람 : 정주희 (서명 또는 인)
B41: ※ 정보이용(해지) 신청 시 준비하실 사항
B42: 1.신청인 또는 국세기본법 제82조의 납세관리인이 신청 시 신분증(주민등록증, 운전면허증, 여권 등)
B43: 2.세무대리인 등 위임받은 사람이 신청 시 위임하는 사람(법인의 경우 법인대표자 등)의 신분증*(사본) 및
B44: 위임받은 사람의 신분증
B45: * 위임하는 사람이 희망하는 경우에 3개월 이내에 발급된 인감증명서(사본), 법인인감증명서(사본),본인서명사실확인서, 전자본인서명사실확인서 가능
B46: ※ 다른 사람의 인장 도용 등 허위로 위임장을 작성하여 신청할 경우에는 「형법」 제231조와 제232조에 따라
B47: 사문서 위ㆍ변조 죄로 5년 이하의 징역 또는 1천만원 이하의 벌금에 처하게 됩니다.
B48: 210mm×297mm[백상지 80g/㎡(재활용품)]

Sheet 국민 EDI
B3: 국민연금 웹 EDI 업무대행 신청서
B5: 접수번호 | D5: 접수일 | F5: 처리기간 | G5: 즉시
B7: 업무 대행기간 | C7: 사업장관리번호 | D7: 306-29-93669-0 | E7: 사업장 명칭 | G7: 위너 세무회계 본점
C8: 소 재 지 | D8: 경기도 성남시 분당구 판교역로 192번길 14-2, 912,913호
C9: 사업자등록번호 | D9: 306-29-93669 | E9: 법인등록번호 | G9: =입력시트!C9 -> 0
C10: 사용자 | D10: 성 명 | F10: 생년월일
D11: 정주희 | F11: 34048
B14: 위탁 사업장 | C14: 사업장관리번호 | D14: =IF(입력시트!C7="","",입력시트!C8 & "-0") | E14: 사업장 명칭 | G14: =입력시트!C7 -> 0
C15: 소 재 지 | D15: =입력시트!C14 -> 0
C16: 사업자등록번호 | D16: =입력시트!C8 -> 0 | E16: 법인등록번호 | G16: =입력시트!C9 -> 0
C17: 사용자 | D17: 성 명 | F17: 생년월일
D18: 성명 | F18: 생년월일
D19: =입력시트!C3 -> 0 | F19: =IF(입력시트!C6="","",TEXT(DATE(IF(LEFT(입력시트!C6,2)*1>25,1900,2000)+LEFT(입력시트!C6,2)*1,MID(입력시트!C6,3,2)*1,MID(입력시트!C6,5,2)*1),"yyyy년 mm월 dd일"))
B22: 업무위탁 | C22: ▪ 자격의 취득 및 상실 신고 ▪ 기준소득월액 변경 등 신고 ▪ 증명서 발급 신청 | F22: ▪ 내용변경 신고 ▪ 신고서 처리결과 및 보험료결정내역 확인
B29: 위탁사업장은 민법 제114조 규정에 따라 국민연금 웹 EDI 업무대행을 위탁하고, 업무대행기관은 대행기관으로서 제반 업무처리에 따른 법적 책임을 부담하며, 각 신청인은 개인정보의 부적정 사용을 방지하기 위한 조치를 취하고 불법 유출 등으로 발생하는 손해배상 등에 대하여 연대하여 책임질 것을 서약하며 업무대행을 신청합니다.
C37: =TODAY() -> 46099
C38: 신청인(업무대행기관 사용자 ) | E38: 정주희 | G38: (서명 또는 인)
C41: 신청인( 업무대행 위탁사업장 사용자 ) | E41: =입력시트!C4 -> 0 | G41: (서명 또는 인)
C43: 국민연금공단 | D43: 분당 | F43: 지사장 귀하
C44: 수수료 없음
C45: 210mm×297mm[일반용지60g/㎡(재활용품)]

Sheet 건강 EDI 
B3: [별지 제6호 서식]
B5: 건강보험 EDI 업무대행 위임장
B6: 업 무 대 행 기 관 | C6: 사업장관리번호 | D6: 306-29-93669-0 | E6: 기 관 명 | F6: 위너 세무회계 본점
C7: 소 재 지 | D7: 경기도 성남시 분당구 판교역로 192번길 14-2, 912, 913호
D8: (전화번호 :010-7276-2430)
C9: 대표자 성명 | D9: 정주희 | E9: 대 표 자 생년월일 | F9: 930320-2 ******
B10: 위 임 사 업 장 | C10: 사업장관리번호 | D10: ='국민 EDI'!D14 | E10: 사업장명 | F10: ='국민 EDI'!G14 -> 0
C11: (단위사업장기호)
C12: 소 재 지 | D12: =입력시트!C14 -> 0
C13: 대표자 성명 | D13: =입력시트!C3 -> 0 | E13: 대 표 자 생년월일 | F13: =LEFT(입력시트!C6,8) & "******" -> ******
C14: 사업자등록번호 | D14: =입력시트!C8 -> 0
B15: 위임 업무범위 | D15: 공단 웹EDI 서비스 업무
B16: 민법 제114조(대리행위의 효력)의 규정에 의하여 위와 같이 건강보험 EDI 업무대행 대리 인 위임을 신청합니다.
B17: =TODAY() -> 46099
B18: =입력시트!C4 & " (서명 또는 인)" -> (서명 또는 인)
B19: 국민건강보험공단 ○○○○지사장 귀하
B20: 이 위임장은 웹EDI를 통하여 '건강보험 EDI 업무대행 위임 신청' 전송 시 첨부하는 서류입니다.
